Workbook

Sheet How to use
B2: AI Customer Support Assistant: ROI Model
B3: Harbor & Thread (fictional) | Step 9 of 11 | Author: Mohammed Omer Ahmed | Version 1.0 (draft)
B5: What it answers | C5: What support costs today, what the AI assistant would cost, how much it would save, and the break-even point: the share of chats the AI must resolve before it pays for itself.
B7: SHEETS
B8: Summary | C8: Headline results and a comparison of the three scenarios.
B9: Inputs | C9: Every assumption, in one place. Change the blue cells to test your own numbers.
B10: Model | C10: All calculations, for the pilot (tiers A and B) and for Phase 2 (adds tier C).
B11: Sensitivity | C11: How the pilot's net benefit changes with the containment rate, the request mix and the vendor fee.
B12: Tier data | C12: The 55 request types and their tiers from the automation matrix (Step 4). The request mix comes from here.
B14: COLOR KEY
B15: Blue text | C15: An input you can change.
B16: Yellow fill | C16: A key assumption that most affects the result.
B17: Green text | C17: A value linked from another sheet.
B18: Black text | C18: A formula. Don't type over it.
B20: KEY CAVEATS
B21: Request mix | C21: The tier shares come from the ABCD dataset, which was built to cover every request type evenly. A real retailer's mix will differ (BRD risk R6), which is why the Sensitivity sheet tests other mixes.
B22: Handle time | C22: The dataset has no chat durations, so the 8 minutes per chat is an assumption from the project brief.
B23: Vendor pricing | C23: AI costs are modeled as a small usage cost on every chat plus a fee per AI-resolved or AI-prepared chat, a common vendor pricing structure. Check current vendor pricing before using these numbers.
B24: Handoffs | C24: Chats handed to an agent are assumed to take the full handle time. Handoff summaries may save time, but that isn't counted, so the savings are conservative.
B25: Containment | C25: The expected containment rate (60%) is the pilot target from the test plan. Step 10 replaces it with the prototype's measured results.
B26: Staffing | C26: Hours saved are shown as full-time-equivalent capacity freed up. How that capacity is used (growth, faster service or staffing changes) is out of scope (BRD section 4.2).
B28: SOURCES
B29: Volume and cost inputs | C29: Project brief, section 11 (docs/01_project_brief.md). Placeholders, to be confirmed with Finance.
B30: Tier shares | C30: Automation matrix (docs/03_automation_matrix.md), from 10,042 conversations.
B31: Targets | C31: Test plan, section 6 (docs/07_test_plan.md).

Sheet Summary
B2: ROI Summary: AI Customer Support Assistant
B3: Expected scenario unless stated. All values link to the Model sheet.
B5: Headline (expected scenario) | C5: Value
B6: Agent cost of chats today (per month) | C6: =Model!C8 -> 128000
B7: Pilot: net annual benefit | C7: =Model!C28 -> 229245.21
B8: Pilot: payback period | C8: =Model!C30 -> 6.2814835
B9: Pilot: break-even containment rate | C9: =Model!C34 -> 0.15300569
B10: Pilot: containment needed to pay back within 12 months | C10: =Model!C35 -> 0.38698797
B11: Phase 2: net annual benefit | C11: =Model!C48 -> 475483.49
B12: Phase 2: share of agent chat workload removed | C12: =Model!C54 -> 0.49298944
B13: Phase 2: agent capacity freed (full-time equivalents) | C13: =Model!C53 -> 14.085413
B15: ="The pilot breaks even once the AI resolves "&TEXT(Model!C34,"0%")&" of tier A and B chats, against a target of "&TEXT(Inputs!C23,"0%")&". At the target, it pays back its one-time cost in about "&TEXT(Model!C30,"0.0")&" months." -> The pilot breaks even once the AI resolves 15% of tier A and B chats, against a target of 60%. At the target, it pays back its one-time cost in about 6.3 months.
B18: Scenario comparison | C18: Worst | D18: Expected | E18: Best
B19: Pilot: net annual benefit | C19: =Model!B28 -> 40743.541 | D19: =Model!C28 -> 229245.21 | E19: =Model!D28 -> 358347.46
B20: Pilot: payback period | C20: =Model!B30 -> 47.124033 | D20: =Model!C30 -> 6.2814835 | E20: =Model!D30 -> 3.0138346
B21: Pilot: break-even containment | C21: =Model!B34 -> 0.30591163 | D21: =Model!C34 -> 0.15300569 | E21: =Model!D34 -> 0.098960833
B22: Phase 2: net annual benefit | C22: =Model!B48 -> 91147.843 | D22: =Model!C48 -> 475483.49 | E22: =Model!D48 -> 725900.94
B23: Phase 2: payback period | C23: =Model!B50 -> 35.546645 | D23: =Model!C50 -> 5.0474939 | E23: =Model!D50 -> 2.4796772
B24: Phase 2: workload removed | C24: =Model!B54 -> 0.28444533 | D24: =Model!C54 -> 0.49298944 | E24: =Model!D54 -> 0.63143547
B25: Phase 2: net benefit over the analysis period | C25: =Model!B51 -> 3443.5301 | D25: =Model!C51 -> 1226450.5 | E25: =Model!D51 -> 2027702.8
B28: Chart data | C28: Pilot | D28: Phase 2
B29: Worst | C29: =Model!B28 -> 40743.541 | D29: =Model!B48 -> 91147.843
B30: Expected | C30: =Model!C28 -> 229245.21 | D30: =Model!C48 -> 475483.49
B31: Best | C31: =Model!D28 -> 358347.46 | D31: =Model!D48 -> 725900.94

Sheet Inputs
A1: Inputs and assumptions
A2: Blue = change me. Yellow = key assumption. Green = linked from another sheet.
A4: Common assumption | B4: Value | C4: Unit | E4: Source
A5: Chats per month | B5: 30000 | C5: chats | E5: Project brief, section 11 (placeholder)
A6: Average agent handle time per chat | B6: 8 | C6: minutes | E6: Project brief, section 11. The dataset has no chat durations (BRD CO-3)
A7: Agent cost per hour, including benefits | B7: 32 | C7: $ / hour | E7: Project brief, section 11 (placeholder)
A8: Support agents | B8: 40 | C8: agents | E8: Project brief, section 11
A9: Productive hours per agent per month | B9: 140 | C9: hours | E9: Assumption: about 35 productive hours a week
A10: Team lead QA review time per week | B10: 6 | C10: hours / week | E10: Assumption for the weekly review (FR-42)
A11: Team lead cost per hour, including benefits | B11: 40 | C11: $ / hour | E11: Assumption
A12: Weeks per month | B12: 4.33 | C12: weeks | E12: 52 weeks ÷ 12 months
A13: Analysis period | B13: 36 | C13: months | E13: Assumption: three years
A15: Request mix by tier | B15: Share
A16: Tier A: AI handles alone | B16: ='Tier data'!H4 -> 0.31517626 | E16: Linked from Tier data (automation matrix). Dataset mix, not a real retailer's mix
A17: Tier B: AI handles after verification | B17: ='Tier data'!H5 -> 0.11959769
A18: Tier C: AI prepares, person approves | B18: ='Tier data'!H6 -> 0.442143
A19: Tier D: people only | B19: ='Tier data'!H7 -> 0.12308305
A20: Total (check: must be 100%) | B20: =SUM(B16:B19) -> 1
A22: Scenario assumption | B22: Worst | C22: Expected | D22: Best | E22: Source
A23: Containment rate: tier A and B chats resolved by AI | B23: 0.4 | C23: 0.6 | D23: 0.75 | E23: Expected = pilot target (test plan, section 6). Step 10 replaces it with measured results
A24: Tier C chats successfully prepared by AI | B24: 0.5 | C24: 0.7 | D24: 0.85 | E24: Assumption. The rest are handed to an agent at full handle time
A25: Agent minutes to review and approve a tier C chat | B25: 4 | C25: 2 | D25: 1.5 | E25: Assumption: one-click approval with evidence shown (FR-36)
A26: AI usage cost per chat (every chat starts with the AI) | B26: 0.2 | C26: 0.1 | D26: 0.05 | E26: Assumption: model and hosting costs per conversation
A27: Vendor fee per AI-resolved or AI-prepared chat | B27: 1.5 | C27: 0.99 | D27: 0.75 | E27: Assumption based on per-resolution vendor pricing. Check current pricing
A28: Fixed platform and maintenance cost per month | B28: 4000 | C28: 2500 | D28: 2000 | E28: Assumption: platform, monitoring and FAQ upkeep
A29: One-time cost: pilot implementation | B29: 160000 | C29: 120000 | D29: 90000 | E29: Assumption: integration, testing (Step 8) and training
A30: One-time cost: additional for Phase 2 | B30: 110000 | C30: 80000 | D30: 60000 | E30: Assumption: approval tool (DE-2), write access, stronger identity check (FR-08)
A32: Example of the expected format: 0.60 shows as 60.0%. Enter percentages as decimals.

Sheet Model
A1: Model: calculations by scenario
A2: All black cells are formulas. Change values on the Inputs sheet.
A4: Monthly figures unless stated | B4: Worst | C4: Expected | D4: Best | E4: How it's calculated
A6: TODAY: every chat handled by an agent
A7: Agent hours spent on chats | B7: =Inputs!$B$5*Inputs!$B$6/60 -> 4000 | C7: =Inputs!$B$5*Inputs!$B$6/60 -> 4000 | D7: =Inputs!$B$5*Inputs!$B$6/60 -> 4000 | E7: Chats × handle time
A8: Agent cost of chats | B8: =B7*Inputs!$B$7 -> 128000 | C8: =C7*Inputs!$B$7 -> 128000 | D8: =D7*Inputs!$B$7 -> 128000 | E8: Hours × cost per hour
A9: Agent capacity (hours) | B9: =Inputs!$B$8*Inputs!$B$9 -> 5600 | C9: =Inputs!$B$8*Inputs!$B$9 -> 5600 | D9: =Inputs!$B$8*Inputs!$B$9 -> 5600 | E9: Agents × productive hours
A10: Capacity used by chats | B10: =IF(B9>0,B7/B9,0) -> 0.71428571 | C10: =IF(C9>0,C7/C9,0) -> 0.71428571 | D10: =IF(D9>0,D7/D9,0) -> 0.71428571 | E10: Check: today's workload fits the team
A12: CHATS BY TIER
A13: Tier A chats | B13: =Inputs!$B$5*Inputs!$B$16 -> 9455.2878 | C13: =Inputs!$B$5*Inputs!$B$16 -> 9455.2878 | D13: =Inputs!$B$5*Inputs!$B$16 -> 9455.2878 | E13: Chats × tier share
A14: Tier B chats | B14: =Inputs!$B$5*Inputs!$B$17 -> 3587.9307 | C14: =Inputs!$B$5*Inputs!$B$17 -> 3587.9307 | D14: =Inputs!$B$5*Inputs!$B$17 -> 3587.9307 | E14: Chats × tier share
A15: Tier C chats | B15: =Inputs!$B$5*Inputs!$B$18 -> 13264.29 | C15: =Inputs!$B$5*Inputs!$B$18 -> 13264.29 | D15: =Inputs!$B$5*Inputs!$B$18 -> 13264.29 | E15: Chats × tier share
A16: Tier D chats | B16: =Inputs!$B$5*Inputs!$B$19 -> 3692.4915 | C16: =Inputs!$B$5*Inputs!$B$19 -> 3692.4915 | D16: =Inputs!$B$5*Inputs!$B$19 -> 3692.4915 | E16: Chats × tier share
A18: PILOT: AI handles tiers A and B
A19: Chats resolved by AI | B19: =(B13+B14)*Inputs!B23 -> 5217.2874 | C19: =(C13+C14)*Inputs!C23 -> 7825.9311 | D19: =(D13+D14)*Inputs!D23 -> 9782.4139 | E19: Tier A and B chats × containment rate
A20: Agent hours saved | B20: =B19*Inputs!$B$6/60 -> 695.63832 | C20: =C19*Inputs!$B$6/60 -> 1043.4575 | D20: =D19*Inputs!$B$6/60 -> 1304.3218 | E20: Resolved chats × handle time
A21: Value of agent time saved | B21: =B20*Inputs!$B$7 -> 22260.426 | C21: =C20*Inputs!$B$7 -> 33390.639 | D21: =D20*Inputs!$B$7 -> 41738.299 | E21: Hours saved × cost per hour
A22: AI usage cost | B22: =Inputs!$B$5*Inputs!B26 -> 6000 | C22: =Inputs!$B$5*Inputs!C26 -> 3000 | D22: =Inputs!$B$5*Inputs!D26 -> 1500 | E22: Every chat starts with the AI
A23: Vendor fees | B23: =B19*Inputs!B27 -> 7825.9311 | C23: =C19*Inputs!C27 -> 7747.6718 | D23: =D19*Inputs!D27 -> 7336.8104 | E23: Resolved chats × fee
A24: Fixed platform cost | B24: =Inputs!B28 -> 4000 | C24: =Inputs!C28 -> 2500 | D24: =Inputs!D28 -> 2000
A25: Team lead QA review cost | B25: =Inputs!$B$10*Inputs!$B$12*Inputs!$B$11 -> 1039.2 | C25: =Inputs!$B$10*Inputs!$B$12*Inputs!$B$11 -> 1039.2 | D25: =Inputs!$B$10*Inputs!$B$12*Inputs!$B$11 -> 1039.2 | E25: Weekly review hours × weeks × cost per hour
A26: Total AI running cost | B26: =SUM(B22:B25) -> 18865.131 | C26: =SUM(C22:C25) -> 14286.872 | D26: =SUM(D22:D25) -> 11876.01
A27: Net monthly benefit | B27: =B21-B26 -> 3395.2951 | C27: =C21-C26 -> 19103.768 | D27: =D21-D26 -> 29862.289 | E27: Value saved − running cost
A28: Net annual benefit | B28: =B27*12 -> 40743.541 | C28: =C27*12 -> 229245.21 | D28: =D27*12 -> 358347.46
A29: One-time implementation cost | B29: =Inputs!B29 -> 160000 | C29: =Inputs!C29 -> 120000 | D29: =Inputs!D29 -> 90000
A30: Payback period (months) | B30: =IF(B27>0,B29/B27,"No payback") -> 47.124033 | C30: =IF(C27>0,C29/C27,"No payback") -> 6.2814835 | D30: =IF(D27>0,D29/D27,"No payback") -> 3.0138346 | E30: One-time cost ÷ net monthly benefit
A31: Net benefit over the analysis period | B31: =B27*Inputs!$B$13-B29 -> -37769.376 | C31: =C27*Inputs!$B$13-C29 -> 567735.63 | D31: =D27*Inputs!$B$13-D29 -> 985042.39 | E31: Net monthly × months − one-time cost
A32: Return on one-time investment | B32: =IF(B29>0,B31/B29,0) -> -0.2360586 | C32: =IF(C29>0,C31/C29,0) -> 4.7311303 | D32: =IF(D29>0,D31/D29,0) -> 10.944915 | E32: Net benefit over the period ÷ one-time cost
A33: Agent capacity freed (full-time equivalents) | B33: =IF(Inputs!$B$9>0,B20/Inputs!$B$9,0) -> 4.9688451 | C33: =IF(Inputs!$B$9>0,C20/Inputs!$B$9,0) -> 7.4532677 | D33: =IF(Inputs!$B$9>0,D20/Inputs!$B$9,0) -> 9.3165846 | E33: Hours saved ÷ productive hours per agent
A34: Break-even containment rate (monthly) | B34: =(B22+B24+B25)/((B13+B14)*(Inputs!$B$6/60*Inputs!$B$7-Inputs!B27)) -> 0.30591163 | C34: =(C22+C24+C25)/((C13+C14)*(Inputs!$B$6/60*Inputs!$B$7-Inputs!C27)) -> 0.15300569 | D34: =(D22+D24+D25)/((D13+D14)*(Inputs!$B$6/60*Inputs!$B$7-Inputs!D27)) -> 0.098960833 | E34: Containment where savings equal running costs
A35: Containment needed to pay back within 12 months | B35: =(B22+B24+B25+B29/12)/((B13+B14)*(Inputs!$B$6/60*Inputs!$B$7-Inputs!B27)) -> 0.67539691 | C35: =(C22+C24+C25+C29/12)/((C13+C14)*(Inputs!$B$6/60*Inputs!$B$7-Inputs!C27)) -> 0.38698797 | D35: =(D22+D24+D25+D29/12)/((D13+D14)*(Inputs!$B$6/60*Inputs!$B$7-Inputs!D27)) -> 0.2624712 | E35: Also covers the one-time cost over 12 months
A37: PHASE 2: adds tier C with agent approval
A38: Tier C chats prepared by AI | B38: =B15*Inputs!B24 -> 6632.145 | C38: =C15*Inputs!C24 -> 9285.003 | D38: =D15*Inputs!D24 -> 11274.646 | E38: Tier C chats × prepared share
A39: Agent hours saved on tier C | B39: =B38*(Inputs!$B$6-Inputs!B25)/60 -> 442.143 | C39: =C38*(Inputs!$B$6-Inputs!C25)/60 -> 928.5003 | D39: =D38*(Inputs!$B$6-Inputs!D25)/60 -> 1221.42 | E39: Prepared chats × (handle time − approval time)
A40: Total agent hours saved | B40: =B20+B39 -> 1137.7813 | C40: =C20+C39 -> 1971.9578 | D40: =D20+D39 -> 2525.7419 | E40: Pilot hours + tier C hours
A41: Value of agent time saved | B41: =B40*Inputs!$B$7 -> 36409.002 | C41: =C40*Inputs!$B$7 -> 63102.649 | D41: =D40*Inputs!$B$7 -> 80823.74
A42: AI usage cost | B42: =B22 -> 6000 | C42: =C22 -> 3000 | D42: =D22 -> 1500 | E42: Same as the pilot
A43: Vendor fees | B43: =(B19+B38)*Inputs!B27 -> 17774.149 | C43: =(C19+C38)*Inputs!C27 -> 16939.825 | D43: =(D19+D38)*Inputs!D27 -> 15792.795 | E43: Resolved and prepared chats × fee
A44: Fixed platform cost | B44: =B24 -> 4000 | C44: =C24 -> 2500 | D44: =D24 -> 2000
A45: Team lead QA review cost | B45: =B25 -> 1039.2 | C45: =C25 -> 1039.2 | D45: =D25 -> 1039.2
...

Sheet Sensitivity
A1: Sensitivity: pilot net monthly benefit
A2: Expected-scenario costs. Green = positive, red = negative. The highlighted column is the dataset's mix.
A4: Table 1: containment rate × share of chats in tiers A and B
A5: Containment ↓ / A+B share → | B5: 0.25 | C5: 0.35 | D5: =Inputs!$B$16+Inputs!$B$17 -> 0.43477395 | E5: 0.55 | F5: 0.65
A6: 0.3 | B6: =$A6*(Inputs!$B$5*B$5)*(Inputs!$B$6/60*Inputs!$B$7-Inputs!$C$27)-(Inputs!$B$5*Inputs!$C$26+Inputs!$C$28+Model!$C$25) -> 833.3 | C6: =$A6*(Inputs!$B$5*C$5)*(Inputs!$B$6/60*Inputs!$B$7-Inputs!$C$27)-(Inputs!$B$5*Inputs!$C$26+Inputs!$C$28+Model!$C$25) -> 3782.3 | D6: =$A6*(Inputs!$B$5*D$5)*(Inputs!$B$6/60*Inputs!$B$7-Inputs!$C$27)-(Inputs!$B$5*Inputs!$C$26+Inputs!$C$28+Model!$C$25) -> 6282.2838 | E6: =$A6*(Inputs!$B$5*E$5)*(Inputs!$B$6/60*Inputs!$B$7-Inputs!$C$27)-(Inputs!$B$5*Inputs!$C$26+Inputs!$C$28+Model!$C$25) -> 9680.3 | F6: =$A6*(Inputs!$B$5*F$5)*(Inputs!$B$6/60*Inputs!$B$7-Inputs!$C$27)-(Inputs!$B$5*Inputs!$C$26+Inputs!$C$28+Model!$C$25) -> 12629.3
A7: 0.4 | B7: =$A7*(Inputs!$B$5*B$5)*(Inputs!$B$6/60*Inputs!$B$7-Inputs!$C$27)-(Inputs!$B$5*Inputs!$C$26+Inputs!$C$28+Model!$C$25) -> 3290.8 | C7: =$A7*(Inputs!$B$5*C$5)*(Inputs!$B$6/60*Inputs!$B$7-Inputs!$C$27)-(Inputs!$B$5*Inputs!$C$26+Inputs!$C$28+Model!$C$25) -> 7222.8 | D7: =$A7*(Inputs!$B$5*D$5)*(Inputs!$B$6/60*Inputs!$B$7-Inputs!$C$27)-(Inputs!$B$5*Inputs!$C$26+Inputs!$C$28+Model!$C$25) -> 10556.112 | E7: =$A7*(Inputs!$B$5*E$5)*(Inputs!$B$6/60*Inputs!$B$7-Inputs!$C$27)-(Inputs!$B$5*Inputs!$C$26+Inputs!$C$28+Model!$C$25) -> 15086.8 | F7: =$A7*(Inputs!$B$5*F$5)*(Inputs!$B$6/60*Inputs!$B$7-Inputs!$C$27)-(Inputs!$B$5*Inputs!$C$26+Inputs!$C$28+Model!$C$25) -> 19018.8
A8: 0.5 | B8: =$A8*(Inputs!$B$5*B$5)*(Inputs!$B$6/60*Inputs!$B$7-Inputs!$C$27)-(Inputs!$B$5*Inputs!$C$26+Inputs!$C$28+Model!$C$25) -> 5748.3 | C8: =$A8*(Inputs!$B$5*C$5)*(Inputs!$B$6/60*Inputs!$B$7-Inputs!$C$27)-(Inputs!$B$5*Inputs!$C$26+Inputs!$C$28+Model!$C$25) -> 10663.3 | D8: =$A8*(Inputs!$B$5*D$5)*(Inputs!$B$6/60*Inputs!$B$7-Inputs!$C$27)-(Inputs!$B$5*Inputs!$C$26+Inputs!$C$28+Model!$C$25) -> 14829.94 | E8: =$A8*(Inputs!$B$5*E$5)*(Inputs!$B$6/60*Inputs!$B$7-Inputs!$C$27)-(Inputs!$B$5*Inputs!$C$26+Inputs!$C$28+Model!$C$25) -> 20493.3 | F8: =$A8*(Inputs!$B$5*F$5)*(Inputs!$B$6/60*Inputs!$B$7-Inputs!$C$27)-(Inputs!$B$5*Inputs!$C$26+Inputs!$C$28+Model!$C$25) -> 25408.3
A9: 0.6 | B9: =$A9*(Inputs!$B$5*B$5)*(Inputs!$B$6/60*Inputs!$B$7-Inputs!$C$27)-(Inputs!$B$5*Inputs!$C$26+Inputs!$C$28+Model!$C$25) -> 8205.8 | C9: =$A9*(Inputs!$B$5*C$5)*(Inputs!$B$6/60*Inputs!$B$7-Inputs!$C$27)-(Inputs!$B$5*Inputs!$C$26+Inputs!$C$28+Model!$C$25) -> 14103.8 | D9: =$A9*(Inputs!$B$5*D$5)*(Inputs!$B$6/60*Inputs!$B$7-Inputs!$C$27)-(Inputs!$B$5*Inputs!$C$26+Inputs!$C$28+Model!$C$25) -> 19103.768 | E9: =$A9*(Inputs!$B$5*E$5)*(Inputs!$B$6/60*Inputs!$B$7-Inputs!$C$27)-(Inputs!$B$5*Inputs!$C$26+Inputs!$C$28+Model!$C$25) -> 25899.8 | F9: =$A9*(Inputs!$B$5*F$5)*(Inputs!$B$6/60*Inputs!$B$7-Inputs!$C$27)-(Inputs!$B$5*Inputs!$C$26+Inputs!$C$28+Model!$C$25) -> 31797.8
A10: 0.7 | B10: =$A10*(Inputs!$B$5*B$5)*(Inputs!$B$6/60*Inputs!$B$7-Inputs!$C$27)-(Inputs!$B$5*Inputs!$C$26+Inputs!$C$28+Model!$C$25) -> 10663.3 | C10: =$A10*(Inputs!$B$5*C$5)*(Inputs!$B$6/60*Inputs!$B$7-Inputs!$C$27)-(Inputs!$B$5*Inputs!$C$26+Inputs!$C$28+Model!$C$25) -> 17544.3 | D10: =$A10*(Inputs!$B$5*D$5)*(Inputs!$B$6/60*Inputs!$B$7-Inputs!$C$27)-(Inputs!$B$5*Inputs!$C$26+Inputs!$C$28+Model!$C$25) -> 23377.595 | E10: =$A10*(Inputs!$B$5*E$5)*(Inputs!$B$6/60*Inputs!$B$7-Inputs!$C$27)-(Inputs!$B$5*Inputs!$C$26+Inputs!$C$28+Model!$C$25) -> 31306.3 | F10: =$A10*(Inputs!$B$5*F$5)*(Inputs!$B$6/60*Inputs!$B$7-Inputs!$C$27)-(Inputs!$B$5*Inputs!$C$26+Inputs!$C$28+Model!$C$25) -> 38187.3
A11: 0.8 | B11: =$A11*(Inputs!$B$5*B$5)*(Inputs!$B$6/60*Inputs!$B$7-Inputs!$C$27)-(Inputs!$B$5*Inputs!$C$26+Inputs!$C$28+Model!$C$25) -> 13120.8 | C11: =$A11*(Inputs!$B$5*C$5)*(Inputs!$B$6/60*Inputs!$B$7-Inputs!$C$27)-(Inputs!$B$5*Inputs!$C$26+Inputs!$C$28+Model!$C$25) -> 20984.8 | D11: =$A11*(Inputs!$B$5*D$5)*(Inputs!$B$6/60*Inputs!$B$7-Inputs!$C$27)-(Inputs!$B$5*Inputs!$C$26+Inputs!$C$28+Model!$C$25) -> 27651.423 | E11: =$A11*(Inputs!$B$5*E$5)*(Inputs!$B$6/60*Inputs!$B$7-Inputs!$C$27)-(Inputs!$B$5*Inputs!$C$26+Inputs!$C$28+Model!$C$25) -> 36712.8 | F11: =$A11*(Inputs!$B$5*F$5)*(Inputs!$B$6/60*Inputs!$B$7-Inputs!$C$27)-(Inputs!$B$5*Inputs!$C$26+Inputs!$C$28+Model!$C$25) -> 44576.8
A12: 0.9 | B12: =$A12*(Inputs!$B$5*B$5)*(Inputs!$B$6/60*Inputs!$B$7-Inputs!$C$27)-(Inputs!$B$5*Inputs!$C$26+Inputs!$C$28+Model!$C$25) -> 15578.3 | C12: =$A12*(Inputs!$B$5*C$5)*(Inputs!$B$6/60*Inputs!$B$7-Inputs!$C$27)-(Inputs!$B$5*Inputs!$C$26+Inputs!$C$28+Model!$C$25) -> 24425.3 | D12: =$A12*(Inputs!$B$5*D$5)*(Inputs!$B$6/60*Inputs!$B$7-Inputs!$C$27)-(Inputs!$B$5*Inputs!$C$26+Inputs!$C$28+Model!$C$25) -> 31925.251 | E12: =$A12*(Inputs!$B$5*E$5)*(Inputs!$B$6/60*Inputs!$B$7-Inputs!$C$27)-(Inputs!$B$5*Inputs!$C$26+Inputs!$C$28+Model!$C$25) -> 42119.3 | F12: =$A12*(Inputs!$B$5*F$5)*(Inputs!$B$6/60*Inputs!$B$7-Inputs!$C$27)-(Inputs!$B$5*Inputs!$C$26+Inputs!$C$28+Model!$C$25) -> 50966.3
A14: The row and column headers can be changed to test other values. The middle column (yellow text) always shows the current mix from Inputs.
A16: Table 2: containment rate × vendor fee per resolved chat (current mix)
A17: Containment ↓ / Fee → | B17: 0.5 | C17: 0.75 | D17: 0.99 | E17: 1.25 | F17: 1.5
A18: 0.3 | B18: =$A18*(Inputs!$B$5*(Inputs!$B$16+Inputs!$B$17))*(Inputs!$B$6/60*Inputs!$B$7-B$17)-(Inputs!$B$5*Inputs!$C$26+Inputs!$C$28+Model!$C$25) -> 8199.6369 | C18: =$A18*(Inputs!$B$5*(Inputs!$B$16+Inputs!$B$17))*(Inputs!$B$6/60*Inputs!$B$7-C$17)-(Inputs!$B$5*Inputs!$C$26+Inputs!$C$28+Model!$C$25) -> 7221.3955 | D18: =$A18*(Inputs!$B$5*(Inputs!$B$16+Inputs!$B$17))*(Inputs!$B$6/60*Inputs!$B$7-D$17)-(Inputs!$B$5*Inputs!$C$26+Inputs!$C$28+Model!$C$25) -> 6282.2838 | E18: =$A18*(Inputs!$B$5*(Inputs!$B$16+Inputs!$B$17))*(Inputs!$B$6/60*Inputs!$B$7-E$17)-(Inputs!$B$5*Inputs!$C$26+Inputs!$C$28+Model!$C$25) -> 5264.9127 | F18: =$A18*(Inputs!$B$5*(Inputs!$B$16+Inputs!$B$17))*(Inputs!$B$6/60*Inputs!$B$7-F$17)-(Inputs!$B$5*Inputs!$C$26+Inputs!$C$28+Model!$C$25) -> 4286.6713
A19: 0.4 | B19: =$A19*(Inputs!$B$5*(Inputs!$B$16+Inputs!$B$17))*(Inputs!$B$6/60*Inputs!$B$7-B$17)-(Inputs!$B$5*Inputs!$C$26+Inputs!$C$28+Model!$C$25) -> 13112.583 | C19: =$A19*(Inputs!$B$5*(Inputs!$B$16+Inputs!$B$17))*(Inputs!$B$6/60*Inputs!$B$7-C$17)-(Inputs!$B$5*Inputs!$C$26+Inputs!$C$28+Model!$C$25) -> 11808.261 | D19: =$A19*(Inputs!$B$5*(Inputs!$B$16+Inputs!$B$17))*(Inputs!$B$6/60*Inputs!$B$7-D$17)-(Inputs!$B$5*Inputs!$C$26+Inputs!$C$28+Model!$C$25) -> 10556.112 | E19: =$A19*(Inputs!$B$5*(Inputs!$B$16+Inputs!$B$17))*(Inputs!$B$6/60*Inputs!$B$7-E$17)-(Inputs!$B$5*Inputs!$C$26+Inputs!$C$28+Model!$C$25) -> 9199.617 | F19: =$A19*(Inputs!$B$5*(Inputs!$B$16+Inputs!$B$17))*(Inputs!$B$6/60*Inputs!$B$7-F$17)-(Inputs!$B$5*Inputs!$C$26+Inputs!$C$28+Model!$C$25) -> 7895.2951
A20: 0.5 | B20: =$A20*(Inputs!$B$5*(Inputs!$B$16+Inputs!$B$17))*(Inputs!$B$6/60*Inputs!$B$7-B$17)-(Inputs!$B$5*Inputs!$C$26+Inputs!$C$28+Model!$C$25) -> 18025.528 | C20: =$A20*(Inputs!$B$5*(Inputs!$B$16+Inputs!$B$17))*(Inputs!$B$6/60*Inputs!$B$7-C$17)-(Inputs!$B$5*Inputs!$C$26+Inputs!$C$28+Model!$C$25) -> 16395.126 | D20: =$A20*(Inputs!$B$5*(Inputs!$B$16+Inputs!$B$17))*(Inputs!$B$6/60*Inputs!$B$7-D$17)-(Inputs!$B$5*Inputs!$C$26+Inputs!$C$28+Model!$C$25) -> 14829.94 | E20: =$A20*(Inputs!$B$5*(Inputs!$B$16+Inputs!$B$17))*(Inputs!$B$6/60*Inputs!$B$7-E$17)-(Inputs!$B$5*Inputs!$C$26+Inputs!$C$28+Model!$C$25) -> 13134.321 | F20: =$A20*(Inputs!$B$5*(Inputs!$B$16+Inputs!$B$17))*(Inputs!$B$6/60*Inputs!$B$7-F$17)-(Inputs!$B$5*Inputs!$C$26+Inputs!$C$28+Model!$C$25) -> 11503.919
A21: 0.6 | B21: =$A21*(Inputs!$B$5*(Inputs!$B$16+Inputs!$B$17))*(Inputs!$B$6/60*Inputs!$B$7-B$17)-(Inputs!$B$5*Inputs!$C$26+Inputs!$C$28+Model!$C$25) -> 22938.474 | C21: =$A21*(Inputs!$B$5*(Inputs!$B$16+Inputs!$B$17))*(Inputs!$B$6/60*Inputs!$B$7-C$17)-(Inputs!$B$5*Inputs!$C$26+Inputs!$C$28+Model!$C$25) -> 20981.991 | D21: =$A21*(Inputs!$B$5*(Inputs!$B$16+Inputs!$B$17))*(Inputs!$B$6/60*Inputs!$B$7-D$17)-(Inputs!$B$5*Inputs!$C$26+Inputs!$C$28+Model!$C$25) -> 19103.768 | E21: =$A21*(Inputs!$B$5*(Inputs!$B$16+Inputs!$B$17))*(Inputs!$B$6/60*Inputs!$B$7-E$17)-(Inputs!$B$5*Inputs!$C$26+Inputs!$C$28+Model!$C$25) -> 17069.025 | F21: =$A21*(Inputs!$B$5*(Inputs!$B$16+Inputs!$B$17))*(Inputs!$B$6/60*Inputs!$B$7-F$17)-(Inputs!$B$5*Inputs!$C$26+Inputs!$C$28+Model!$C$25) -> 15112.543
A22: 0.7 | B22: =$A22*(Inputs!$B$5*(Inputs!$B$16+Inputs!$B$17))*(Inputs!$B$6/60*Inputs!$B$7-B$17)-(Inputs!$B$5*Inputs!$C$26+Inputs!$C$28+Model!$C$25) -> 27851.419 | C22: =$A22*(Inputs!$B$5*(Inputs!$B$16+Inputs!$B$17))*(Inputs!$B$6/60*Inputs!$B$7-C$17)-(Inputs!$B$5*Inputs!$C$26+Inputs!$C$28+Model!$C$25) -> 25568.856 | D22: =$A22*(Inputs!$B$5*(Inputs!$B$16+Inputs!$B$17))*(Inputs!$B$6/60*Inputs!$B$7-D$17)-(Inputs!$B$5*Inputs!$C$26+Inputs!$C$28+Model!$C$25) -> 23377.595 | E22: =$A22*(Inputs!$B$5*(Inputs!$B$16+Inputs!$B$17))*(Inputs!$B$6/60*Inputs!$B$7-E$17)-(Inputs!$B$5*Inputs!$C$26+Inputs!$C$28+Model!$C$25) -> 21003.73 | F22: =$A22*(Inputs!$B$5*(Inputs!$B$16+Inputs!$B$17))*(Inputs!$B$6/60*Inputs!$B$7-F$17)-(Inputs!$B$5*Inputs!$C$26+Inputs!$C$28+Model!$C$25) -> 18721.166
A23: 0.8 | B23: =$A23*(Inputs!$B$5*(Inputs!$B$16+Inputs!$B$17))*(Inputs!$B$6/60*Inputs!$B$7-B$17)-(Inputs!$B$5*Inputs!$C$26+Inputs!$C$28+Model!$C$25) -> 32764.365 | C23: =$A23*(Inputs!$B$5*(Inputs!$B$16+Inputs!$B$17))*(Inputs!$B$6/60*Inputs!$B$7-C$17)-(Inputs!$B$5*Inputs!$C$26+Inputs!$C$28+Model!$C$25) -> 30155.721 | D23: =$A23*(Inputs!$B$5*(Inputs!$B$16+Inputs!$B$17))*(Inputs!$B$6/60*Inputs!$B$7-D$17)-(Inputs!$B$5*Inputs!$C$26+Inputs!$C$28+Model!$C$25) -> 27651.423 | E23: =$A23*(Inputs!$B$5*(Inputs!$B$16+Inputs!$B$17))*(Inputs!$B$6/60*Inputs!$B$7-E$17)-(Inputs!$B$5*Inputs!$C$26+Inputs!$C$28+Model!$C$25) -> 24938.434 | F23: =$A23*(Inputs!$B$5*(Inputs!$B$16+Inputs!$B$17))*(Inputs!$B$6/60*Inputs!$B$7-F$17)-(Inputs!$B$5*Inputs!$C$26+Inputs!$C$28+Model!$C$25) -> 22329.79
A24: 0.9 | B24: =$A24*(Inputs!$B$5*(Inputs!$B$16+Inputs!$B$17))*(Inputs!$B$6/60*Inputs!$B$7-B$17)-(Inputs!$B$5*Inputs!$C$26+Inputs!$C$28+Model!$C$25) -> 37677.311 | C24: =$A24*(Inputs!$B$5*(Inputs!$B$16+Inputs!$B$17))*(Inputs!$B$6/60*Inputs!$B$7-C$17)-(Inputs!$B$5*Inputs!$C$26+Inputs!$C$28+Model!$C$25) -> 34742.586 | D24: =$A24*(Inputs!$B$5*(Inputs!$B$16+Inputs!$B$17))*(Inputs!$B$6/60*Inputs!$B$7-D$17)-(Inputs!$B$5*Inputs!$C$26+Inputs!$C$28+Model!$C$25) -> 31925.251 | E24: =$A24*(Inputs!$B$5*(Inputs!$B$16+Inputs!$B$17))*(Inputs!$B$6/60*Inputs!$B$7-E$17)-(Inputs!$B$5*Inputs!$C$26+Inputs!$C$28+Model!$C$25) -> 28873.138 | F24: =$A24*(Inputs!$B$5*(Inputs!$B$16+Inputs!$B$17))*(Inputs!$B$6/60*Inputs!$B$7-F$17)-(Inputs!$B$5*Inputs!$C$26+Inputs!$C$28+Model!$C$25) -> 25938.414
A26: How to read it: each cell is the pilot's net monthly benefit. Table 1 shows the biggest risk (BRD R6): if the real request mix has fewer tier A and B chats than the dataset, savings shrink, but the pilot still pays for itself in most cells.

Sheet Tier data
A1: Request types by tier (from the automation matrix, Step 4)
A3: Request type | B3: Category | C3: Tier | D3: Conversations | F3: Tier | G3: Conversations | H3: Share
A4: boots | B4: Product and store FAQs | C4: A | D4: 281 | F4: A | G4: =SUMIF($C$4:$C$58,F4,$D$4:$D$58) -> 3165 | H4: =G4/$G$8 -> 0.31517626
A5: membership | B5: Product and store FAQs | C5: A | D5: 281 | F5: B | G5: =SUMIF($C$4:$C$58,F5,$D$4:$D$58) -> 1201 | H5: =G5/$G$8 -> 0.11959769
A6: pricing | B6: Product and store FAQs | C6: A | D6: 277 | F6: C | G6: =SUMIF($C$4:$C$58,F6,$D$4:$D$58) -> 4440 | H6: =G6/$G$8 -> 0.442143
A7: policy | B7: Product and store FAQs | C7: A | D7: 272 | F7: D | G7: =SUMIF($C$4:$C$58,F7,$D$4:$D$58) -> 1236 | H7: =G7/$G$8 -> 0.12308305
A8: timing | B8: Product and store FAQs | C8: A | D8: 264 | F8: Total | G8: =SUM(G4:G7) -> 10042 | H8: =SUM(H4:H7) -> 1
A9: jacket | B9: Product and store FAQs | C9: A | D9: 263
A10: jeans | B10: Product and store FAQs | C10: A | D10: 252
A11: shirt | B11: Product and store FAQs | C11: A | D11: 249
A12: credit_card | B12: Website troubleshooting | C12: A | D12: 266
A13: search_results | B13: Website troubleshooting | C13: A | D13: 259
A14: shopping_cart | B14: Website troubleshooting | C14: A | D14: 251
A15: slow_speed | B15: Website troubleshooting | C15: A | D15: 250
A16: recover_username | B16: Account access | C16: B | D16: 361
A17: refund_status | B17: Refunds and returns | C17: B | D17: 179
A18: status | B18: Shipping | C18: B | D18: 268
A19: status_due_amount | B19: Subscription | C19: B | D19: 185
A20: status_due_date | B20: Subscription | C20: B | D20: 178
... A58: mistimed_billing_already_returned | B58: Purchase disputes | C58: D | D58: 137
A59: Total | D59: =SUM(D4:D58) -> 10042
A60: Source: docs/automation_matrix.csv, conversation counts from the ABCD dataset (10,042 conversations).
